[0m12:40:39  Running with dbt=1.9.3
[0m12:40:40  Registered adapter: bigquery=1.9.1
[0m12:40:41  Unable to do partial parsing because config vars, config profile, or config target have changed
[0m12:40:41  Found 2 models, 1 source, 491 macros
[0m12:40:41  
[0m12:40:41  Concurrency: 1 threads (target='dev')
[0m12:40:41  
[0m12:40:42  Encountered an error:
('invalid_grant: Invalid JWT Signature.', {'error': 'invalid_grant', 'error_description': 'Invalid JWT Signature.'})
[0m12:40:42  Traceback (most recent call last):
  File "/home/josh/heart-attack-prediction/venv/lib/python3.12/site-packages/dbt/cli/requires.py", line 153, in wrapper
    result, success = func(*args, **kwargs)
                      ^^^^^^^^^^^^^^^^^^^^^
  File "/home/josh/heart-attack-prediction/venv/lib/python3.12/site-packages/dbt/cli/requires.py", line 103, in wrapper
    return func(*args, **kwargs)
           ^^^^^^^^^^^^^^^^^^^^^
  File "/home/josh/heart-attack-prediction/venv/lib/python3.12/site-packages/dbt/cli/requires.py", line 235, in wrapper
    return func(*args, **kwargs)
           ^^^^^^^^^^^^^^^^^^^^^
  File "/home/josh/heart-attack-prediction/venv/lib/python3.12/site-packages/dbt/cli/requires.py", line 264, in wrapper
    return func(*args, **kwargs)
           ^^^^^^^^^^^^^^^^^^^^^
  File "/home/josh/heart-attack-prediction/venv/lib/python3.12/site-packages/dbt/cli/requires.py", line 311, in wrapper
    return func(*args, **kwargs)
           ^^^^^^^^^^^^^^^^^^^^^
  File "/home/josh/heart-attack-prediction/venv/lib/python3.12/site-packages/dbt/cli/requires.py", line 328, in wrapper
    return func(*args, **kwargs)
           ^^^^^^^^^^^^^^^^^^^^^
  File "/home/josh/heart-attack-prediction/venv/lib/python3.12/site-packages/dbt/cli/main.py", line 341, in compile
    results = task.run()
              ^^^^^^^^^^
  File "/home/josh/heart-attack-prediction/venv/lib/python3.12/site-packages/dbt/task/runnable.py", line 590, in run
    result = self.execute_with_hooks(selected_uids)
             ^^^^^^^^^^^^^^^^^^^^^^^^^^^^^^^^^^^^^^
  File "/home/josh/heart-attack-prediction/venv/lib/python3.12/site-packages/dbt/task/runnable.py", line 528, in execute_with_hooks
    before_run_status = self.before_run(adapter, selected_uids)
                        ^^^^^^^^^^^^^^^^^^^^^^^^^^^^^^^^^^^^^^^
  File "/home/josh/heart-attack-prediction/venv/lib/python3.12/site-packages/dbt/task/runnable.py", line 504, in before_run
    self.populate_adapter_cache(adapter)
  File "/home/josh/heart-attack-prediction/venv/lib/python3.12/site-packages/dbt/task/runnable.py", line 494, in populate_adapter_cache
    adapter.set_relations_cache(cachable_nodes)
  File "/home/josh/heart-attack-prediction/venv/lib/python3.12/site-packages/dbt/adapters/base/impl.py", line 610, in set_relations_cache
    self._relations_cache_for_schemas(relation_configs, required_schemas)
  File "/home/josh/heart-attack-prediction/venv/lib/python3.12/site-packages/dbt/adapters/base/impl.py", line 586, in _relations_cache_for_schemas
    for relation in future.result():
                    ^^^^^^^^^^^^^^^
  File "/usr/lib/python3.12/concurrent/futures/_base.py", line 449, in result
    return self.__get_result()
           ^^^^^^^^^^^^^^^^^^^
  File "/usr/lib/python3.12/concurrent/futures/_base.py", line 401, in __get_result
    raise self._exception
  File "/usr/lib/python3.12/concurrent/futures/thread.py", line 58, in run
    result = self.fn(*self.args, **self.kwargs)
             ^^^^^^^^^^^^^^^^^^^^^^^^^^^^^^^^^^
  File "/home/josh/heart-attack-prediction/venv/lib/python3.12/site-packages/dbt_common/utils/executor.py", line 16, in connected
    return func(*args, **kwargs)
           ^^^^^^^^^^^^^^^^^^^^^
  File "/home/josh/heart-attack-prediction/venv/lib/python3.12/site-packages/dbt/adapters/bigquery/impl.py", line 293, in list_relations_without_caching
    return [self._bq_table_to_relation(table) for table in all_tables]  # type: ignore[misc]
           ^^^^^^^^^^^^^^^^^^^^^^^^^^^^^^^^^^^^^^^^^^^^^^^^^^^^^^^^^^^
  File "/home/josh/heart-attack-prediction/venv/lib/python3.12/site-packages/google/api_core/page_iterator.py", line 208, in _items_iter
    for page in self._page_iter(increment=False):
  File "/home/josh/heart-attack-prediction/venv/lib/python3.12/site-packages/google/api_core/page_iterator.py", line 244, in _page_iter
    page = self._next_page()
           ^^^^^^^^^^^^^^^^^
  File "/home/josh/heart-attack-prediction/venv/lib/python3.12/site-packages/google/api_core/page_iterator.py", line 373, in _next_page
    response = self._get_next_page_response()
               ^^^^^^^^^^^^^^^^^^^^^^^^^^^^^^
  File "/home/josh/heart-attack-prediction/venv/lib/python3.12/site-packages/google/api_core/page_iterator.py", line 432, in _get_next_page_response
    return self.api_request(
           ^^^^^^^^^^^^^^^^^
  File "/home/josh/heart-attack-prediction/venv/lib/python3.12/site-packages/google/cloud/bigquery/client.py", line 1661, in api_request
    return self._call_api(
           ^^^^^^^^^^^^^^^
  File "/home/josh/heart-attack-prediction/venv/lib/python3.12/site-packages/google/cloud/bigquery/client.py", line 843, in _call_api
    return call()
           ^^^^^^
  File "/home/josh/heart-attack-prediction/venv/lib/python3.12/site-packages/google/api_core/retry/retry_unary.py", line 293, in retry_wrapped_func
    return retry_target(
           ^^^^^^^^^^^^^
  File "/home/josh/heart-attack-prediction/venv/lib/python3.12/site-packages/google/api_core/retry/retry_unary.py", line 153, in retry_target
    _retry_error_helper(
  File "/home/josh/heart-attack-prediction/venv/lib/python3.12/site-packages/google/api_core/retry/retry_base.py", line 212, in _retry_error_helper
    raise final_exc from source_exc
  File "/home/josh/heart-attack-prediction/venv/lib/python3.12/site-packages/google/api_core/retry/retry_unary.py", line 144, in retry_target
    result = target()
             ^^^^^^^^
  File "/home/josh/heart-attack-prediction/venv/lib/python3.12/site-packages/google/cloud/_http/__init__.py", line 482, in api_request
    response = self._make_request(
               ^^^^^^^^^^^^^^^^^^^
  File "/home/josh/heart-attack-prediction/venv/lib/python3.12/site-packages/google/cloud/_http/__init__.py", line 341, in _make_request
    return self._do_request(
           ^^^^^^^^^^^^^^^^^
  File "/home/josh/heart-attack-prediction/venv/lib/python3.12/site-packages/google/cloud/_http/__init__.py", line 379, in _do_request
    return self.http.request(
           ^^^^^^^^^^^^^^^^^^
  File "/home/josh/heart-attack-prediction/venv/lib/python3.12/site-packages/google/auth/transport/requests.py", line 533, in request
    self.credentials.before_request(auth_request, method, url, request_headers)
  File "/home/josh/heart-attack-prediction/venv/lib/python3.12/site-packages/google/auth/credentials.py", line 239, in before_request
    self._blocking_refresh(request)
  File "/home/josh/heart-attack-prediction/venv/lib/python3.12/site-packages/google/auth/credentials.py", line 202, in _blocking_refresh
    self.refresh(request)
  File "/home/josh/heart-attack-prediction/venv/lib/python3.12/site-packages/google/oauth2/service_account.py", line 448, in refresh
    access_token, expiry, _ = _client.jwt_grant(
                              ^^^^^^^^^^^^^^^^^^
  File "/home/josh/heart-attack-prediction/venv/lib/python3.12/site-packages/google/oauth2/_client.py", line 299, in jwt_grant
    response_data = _token_endpoint_request(
                    ^^^^^^^^^^^^^^^^^^^^^^^^
  File "/home/josh/heart-attack-prediction/venv/lib/python3.12/site-packages/google/oauth2/_client.py", line 270, in _token_endpoint_request
    _handle_error_response(response_data, retryable_error)
  File "/home/josh/heart-attack-prediction/venv/lib/python3.12/site-packages/google/oauth2/_client.py", line 69, in _handle_error_response
    raise exceptions.RefreshError(
google.auth.exceptions.RefreshError: ('invalid_grant: Invalid JWT Signature.', {'error': 'invalid_grant', 'error_description': 'Invalid JWT Signature.'})

